Cloud-init v. 22.2.2 running 'init' at Sun, 15 Jun 2025 09:37:34 +0000. Up 6.34 seconds.
ci-info: +++++++++++++++++++++++++++++++++++++Net device info++++++++++++++++++++++++++++++++++++++
ci-info: +--------+------+---------------------------+---------------+--------+-------------------+
ci-info: | Device |  Up  |          Address          |      Mask     | Scope  |     Hw-Address    |
ci-info: +--------+------+---------------------------+---------------+--------+-------------------+
ci-info: |  ens5  | True |       172.31.15.128       | 255.255.240.0 | global | 02:8e:63:45:0f:9b |
ci-info: |  ens5  | True | fe80::8e:63ff:fe45:f9b/64 |       .       |  link  | 02:8e:63:45:0f:9b |
ci-info: |   lo   | True |         127.0.0.1         |   255.0.0.0   |  host  |         .         |
ci-info: |   lo   | True |          ::1/128          |       .       |  host  |         .         |
ci-info: +--------+------+---------------------------+---------------+--------+-------------------+
ci-info: +++++++++++++++++++++++++++++Route IPv4 info++++++++++++++++++++++++++++++
ci-info: +-------+-------------+------------+-----------------+-----------+-------+
ci-info: | Route | Destination |  Gateway   |     Genmask     | Interface | Flags |
ci-info: +-------+-------------+------------+-----------------+-----------+-------+
ci-info: |   0   |   0.0.0.0   | 172.31.0.1 |     0.0.0.0     |    ens5   |   UG  |
ci-info: |   1   |  172.31.0.0 |  0.0.0.0   |  255.255.240.0  |    ens5   |   U   |
ci-info: |   2   |  172.31.0.1 |  0.0.0.0   | 255.255.255.255 |    ens5   |   UH  |
ci-info: |   3   |  172.31.0.2 |  0.0.0.0   | 255.255.255.255 |    ens5   |   UH  |
ci-info: +-------+-------------+------------+-----------------+-----------+-------+
ci-info: +++++++++++++++++++Route IPv6 info+++++++++++++++++++
ci-info: +-------+-------------+---------+-----------+-------+
ci-info: | Route | Destination | Gateway | Interface | Flags |
ci-info: +-------+-------------+---------+-----------+-------+
ci-info: |   0   |  fe80::/64  |    ::   |    ens5   |   U   |
ci-info: |   2   |    local    |    ::   |    ens5   |   U   |
ci-info: |   3   |  multicast  |    ::   |    ens5   |   U   |
ci-info: +-------+-------------+---------+-----------+-------+
2025-06-15 09:37:35,202 - url_helper.py[WARNING]: Exception(s) [UrlError("HTTPConnectionPool(host='169.254.169.254', port=80): Max retries exceeded with url: /latest/api/token (Caused by NewConnectionError('<urllib3.connection.HTTPConnection object at 0x7fa1e0e668b0>: Failed to establish a new connection: [Errno 111] Connection refused'))"), UrlError("HTTPConnectionPool(host='fd00:ec2::254', port=80): Max retries exceeded with url: /latest/api/token (Caused by NewConnectionError('<urllib3.connection.HTTPConnection object at 0x7fa1e0e832b0>: Failed to establish a new connection: [Errno 101] Network is unreachable'))")] during request to http://[fd00:ec2::254]:80/latest/api/token, raising last exception
2025-06-15 09:37:35,202 - url_helper.py[WARNING]: Calling 'None' failed [0/240s]: request error [HTTPConnectionPool(host='fd00:ec2::254', port=80): Max retries exceeded with url: /latest/api/token (Caused by NewConnectionError('<urllib3.connection.HTTPConnection object at 0x7fa1e0e832b0>: Failed to establish a new connection: [Errno 101] Network is unreachable'))]
2025-06-15 09:37:35,606 - url_helper.py[WARNING]: Exception(s) [UrlError("HTTPConnectionPool(host='169.254.169.254', port=80): Max retries exceeded with url: /latest/api/token (Caused by NewConnectionError('<urllib3.connection.HTTPConnection object at 0x7fa1e0e14670>: Failed to establish a new connection: [Errno 111] Connection refused'))"), UrlError("HTTPConnectionPool(host='fd00:ec2::254', port=80): Max retries exceeded with url: /latest/api/token (Caused by NewConnectionError('<urllib3.connection.HTTPConnection object at 0x7fa1e0e14fd0>: Failed to establish a new connection: [Errno 101] Network is unreachable'))")] during request to http://[fd00:ec2::254]:80/latest/api/token, raising last exception
2025-06-15 09:37:35,606 - url_helper.py[WARNING]: Calling 'None' failed [0/240s]: request error [HTTPConnectionPool(host='fd00:ec2::254', port=80): Max retries exceeded with url: /latest/api/token (Caused by NewConnectionError('<urllib3.connection.HTTPConnection object at 0x7fa1e0e14fd0>: Failed to establish a new connection: [Errno 101] Network is unreachable'))]
Generating public/private ed25519 key pair.
Your identification has been saved in /etc/ssh/ssh_host_ed25519_key
Your public key has been saved in /etc/ssh/ssh_host_ed25519_key.pub
The key fingerprint is:
SHA256:EVJn7J/r59IFFjfHs77dwcOs4y95j+Uv2ZRqzeRTa1c root@ip-172-31-15-128.ap-northeast-2.compute.internal
The key's randomart image is:
+--[ED25519 256]--+
|      ..o.o    . |
|       . +.   .o+|
|        ..     o=|
|         ..   o. |
|        S  . o=..|
|            o  XE|
|             oO=@|
|            oB=&=|
|           .+=OoO|
+----[SHA256]-----+
Generating public/private ecdsa key pair.
Your identification has been saved in /etc/ssh/ssh_host_ecdsa_key
Your public key has been saved in /etc/ssh/ssh_host_ecdsa_key.pub
The key fingerprint is:
SHA256:c15oT4z2DGOq+pk/J+3bmWUpYEi029NI+D+8F02+bnw root@ip-172-31-15-128.ap-northeast-2.compute.internal
The key's randomart image is:
+---[ECDSA 256]---+
|        .        |
|       . o       |
|        + .      |
|       . * *    .|
|        S ^ =  + |
|         X &  ..o|
|        ... O =..|
|       +o o. O.+E|
|    .o=..=o.=.o..|
+----[SHA256]-----+
Cloud-init v. 22.2.2 running 'modules:config' at Sun, 15 Jun 2025 09:37:38 +0000. Up 10.23 seconds.
Cloud-init v. 22.2.2 running 'modules:final' at Sun, 15 Jun 2025 09:37:39 +0000. Up 11.24 seconds.
